Workbook

Sheet Dashboard
B2: Dashboard — Colegio Secundario
B3: Panel de indicadores generales (se actualiza solo al cargar más datos)
B5: Total de Alumnos | F5: Total de Profesores | J5: Total de Cursos
B6: =COUNTA(Alumnos!$A$2:$A$31) -> 30 | F6: =COUNTA(Profesores!$A$2:$A$12) -> 11 | J6: =SUMPRODUCT(1/COUNTIFS(Alumnos!$F$2:$F$31,Alumnos!$F$2:$F$31,Alumnos!$G$2:$G$31,Alumnos!$G$2:$G$31)) -> 3
B9: Promedio General Institucional | F9: % Asistencia General
B10: =IFERROR(ROUND(AVERAGE(Notas!$K$2:$K$241),2),"") -> 7.07 | F10: =IFERROR(COUNTIF(Asistencia!$G$2:$G$151,"Presente")/COUNTA(Asistencia!$G$2:$G$151),"") -> 0.56
B14: Alumnos por Curso
B15: Curso | C15: Turno | D15: Cant. Alumnos | E15: Promedio del Curso | F15: % Asistencia
B16: 1°A | C16: Mañana | D16: =COUNTIFS(Alumnos!$F$2:$F$31,1,Alumnos!$G$2:$G$31,"A") -> 10 | E16: =IFERROR(ROUND(AVERAGEIFS(Notas!$K$2:$K$241,Notas!$C$2:$C$241,1,Notas!$D$2:$D$241,"A"),2),"") -> 7.18 | F16: =IFERROR(COUNTIFS(Asistencia!$B$2:$B$151,1,Asistencia!$C$2:$C$151,"A",Asistencia!$G$2:$G$151,"Presente")/COUNTIFS(Asistencia!$B$2:$B$151,1,Asistencia!$C$2:$C$151,"A"),"") -> 0.52
B17: 2°A | C17: Mañana | D17: =COUNTIFS(Alumnos!$F$2:$F$31,2,Alumnos!$G$2:$G$31,"A") -> 10 | E17: =IFERROR(ROUND(AVERAGEIFS(Notas!$K$2:$K$241,Notas!$C$2:$C$241,2,Notas!$D$2:$D$241,"A"),2),"") -> 7.16 | F17: =IFERROR(COUNTIFS(Asistencia!$B$2:$B$151,2,Asistencia!$C$2:$C$151,"A",Asistencia!$G$2:$G$151,"Presente")/COUNTIFS(Asistencia!$B$2:$B$151,2,Asistencia!$C$2:$C$151,"A"),"") -> 0.5
B18: 3°A | C18: Tarde | D18: =COUNTIFS(Alumnos!$F$2:$F$31,3,Alumnos!$G$2:$G$31,"A") -> 10 | E18: =IFERROR(ROUND(AVERAGEIFS(Notas!$K$2:$K$241,Notas!$C$2:$C$241,3,Notas!$D$2:$D$241,"A"),2),"") -> 6.87 | F18: =IFERROR(COUNTIFS(Asistencia!$B$2:$B$151,3,Asistencia!$C$2:$C$151,"A",Asistencia!$G$2:$G$151,"Presente")/COUNTIFS(Asistencia!$B$2:$B$151,3,Asistencia!$C$2:$C$151,"A"),"") -> 0.66
B21: Promedio por Materia (todos los cursos) | F21: Distribución de Asistencia (general)
B22: Materia | C22: Promedio | F22: Estado | G22: Cantidad
B23: Biología | C23: =IFERROR(ROUND(AVERAGEIFS(Notas!$K$2:$K$241,Notas!$E$2:$E$241,$B23),2),"") -> 7.1 | F23: Presente | G23: =COUNTIF(Asistencia!$G$2:$G$151,$F23) -> 84
B24: Educación Artística | C24: =IFERROR(ROUND(AVERAGEIFS(Notas!$K$2:$K$241,Notas!$E$2:$E$241,$B24),2),"") -> 6.67 | F24: Ausente | G24: =COUNTIF(Asistencia!$G$2:$G$151,$F24) -> 23
B25: Educación Física | C25: =IFERROR(ROUND(AVERAGEIFS(Notas!$K$2:$K$241,Notas!$E$2:$E$241,$B25),2),"") -> 6.89 | F25: Tarde | G25: =COUNTIF(Asistencia!$G$2:$G$151,$F25) -> 30
B26: Formación Ética y Ciudadana | C26: =IFERROR(ROUND(AVERAGEIFS(Notas!$K$2:$K$241,Notas!$E$2:$E$241,$B26),2),"") -> 7.67 | F26: Justificada | G26: =COUNTIF(Asistencia!$G$2:$G$151,$F26) -> 13
B27: Física-Química | C27: =IFERROR(ROUND(AVERAGEIFS(Notas!$K$2:$K$241,Notas!$E$2:$E$241,$B27),2),"") -> 6.97
B28: Geografía | C28: =IFERROR(ROUND(AVERAGEIFS(Notas!$K$2:$K$241,Notas!$E$2:$E$241,$B28),2),"") -> 7.37
B29: Historia | C29: =IFERROR(ROUND(AVERAGEIFS(Notas!$K$2:$K$241,Notas!$E$2:$E$241,$B29),2),"") -> 7.14
B30: Inglés | C30: =IFERROR(ROUND(AVERAGEIFS(Notas!$K$2:$K$241,Notas!$E$2:$E$241,$B30),2),"") -> 6.89
B31: Lengua y Literatura | C31: =IFERROR(ROUND(AVERAGEIFS(Notas!$K$2:$K$241,Notas!$E$2:$E$241,$B31),2),"") -> 7.04
B32: Matemática | C32: =IFERROR(ROUND(AVERAGEIFS(Notas!$K$2:$K$241,Notas!$E$2:$E$241,$B32),2),"") -> 7.01
B33: Tecnología | C33: =IFERROR(ROUND(AVERAGEIFS(Notas!$K$2:$K$241,Notas!$E$2:$E$241,$B33),2),"") -> 7.17

Sheet Instrucciones
B2: Sistema de Gestión Escolar — Nivel Secundario
B4: Cómo está organizada esta planilla
B6: • Alumnos | C6: Ficha completa de cada alumno/a: datos personales y datos de padre, madre y/o tutor. Es la base de la que se alimentan las demás hojas.
B8: • Profesores | C8: Datos de contacto de cada docente y qué materia dicta principalmente.
B10: • Plan_Materias | C10: Qué materias corresponden a cada Año/División/Turno y qué profesor/a la dicta. Es el 'mapa' curricular del colegio.
B12: • Notas | C12: Listado de alumnos por materia con sus notas y una observación. El promedio y la condición (Aprobado/Desaprobado) se calculan solos.
B14: • Asistencia (Preceptoría) | C14: Toma de lista diaria por curso: Presente / Ausente / Tarde / Justificada, con observación del preceptor/a.
B16: • Dashboard | C16: Panel con indicadores generales: cantidad de alumnos, promedios por materia, asistencia por curso y gráficos.
B19: Referencia de colores
C21: Celdas para completar / editar (datos a cargar)
C22: Celdas con fórmula: no escribir encima, se recalculan solas
B24: Notas importantes
B25: - Los datos de alumnos, profesores, notas y asistencia de esta planilla son EJEMPLOS ilustrativos para mostrar cómo funciona el sistema. Reemplácenlos por los datos reales del colegio.
B26: - Para agregar un alumno nuevo: cargarlo en 'Alumnos' con un ID_Alumno único, y luego agregar sus filas en 'Notas' y 'Asistencia' usando ese mismo ID (el nombre se completa solo).
B27: - Para agregar una materia o cambiar el profesor de un curso: editar la hoja 'Plan_Materias'.
B28: - El Dashboard se actualiza automáticamente a medida que se cargan más alumnos, notas y asistencias.

Sheet Alumnos
A1: ID_Alumno | B1: Apellido | C1: Nombre | D1: DNI | E1: Fecha_Nac. | F1: Año | G1: División | H1: Turno | I1: Dirección | J1: Teléfono_Alumno | K1: Email_Alumno | L1: Apellido_Padre | M1: Nombre_Padre | N1: DNI_Padre | O1: Teléfono_Padre | P1: Apellido_Madre | Q1: Nombre_Madre | R1: DNI_Madre | S1: Teléfono_Madre | T1: Apellido_Tutor | U1: Nombre_Tutor | V1: DNI_Tutor | W1: Teléfono_Tutor | X1: Observaciones
A2: AL-001 | B2: Ortiz | C2: María | D2: 34614226 | E2: 08/04/2013 | F2: 1 | G2: A | H2: Mañana | I2: Calle Díaz 939 | J2: 11-7467-2424 | K2: maría.ortiz@alumnos.ejemplo.edu.ar | L2: Aguirre | M2: Facundo | N2: 30533224 | O2: 11-3244-2535 | P2: Pérez | Q2: Camila | R2: 38478454 | S2: 11-7931-1434
A3: AL-002 | B3: Herrera | C3: Delfina | D3: 37038374 | E3: 08/08/2013 | F3: 1 | G3: A | H3: Mañana | I3: Calle Aguirre 2378 | J3: 11-3053-3615 | K3: delfina.herrera@alumnos.ejemplo.edu.ar | L3: Molina | M3: Facundo | N3: 35708456 | O3: 11-5276-3547 | P3: Pérez | Q3: Zoe | R3: 35647119 | S3: 11-3837-2519
A4: AL-003 | B4: Vega | C4: Joaquín | D4: 34437923 | E4: 26/01/2013 | F4: 1 | G4: A | H4: Mañana | I4: Calle Ortiz 3863 | J4: 11-7392-3045 | K4: joaquín.vega@alumnos.ejemplo.edu.ar | L4: Peralta | M4: Facundo | N4: 31322047 | O4: 11-7522-5803 | P4: Ibáñez | Q4: Pilar | R4: 40377039 | S4: 11-5962-4150
A5: AL-004 | B5: Silva | C5: Tomás | D5: 34855124 | E5: 03/04/2013 | F5: 1 | G5: A | H5: Mañana | I5: Calle Cabrera 927 | J5: 11-6113-5554 | K5: tomás.silva@alumnos.ejemplo.edu.ar | L5: Acosta | M5: Nicolás | N5: 43994050 | O5: 11-5988-3664 | P5: Torres | Q5: Julieta | R5: 33514944 | S5: 11-5187-2169
A6: AL-005 | B6: Sánchez | C6: Franco | D6: 32741438 | E6: 15/07/2013 | F6: 1 | G6: A | H6: Mañana | I6: Calle Romero 4662 | J6: 11-4799-6313 | K6: franco.sánchez@alumnos.ejemplo.edu.ar | L6: Ibáñez | M6: Agustín | N6: 43019118 | O6: 11-3458-4752 | P6: Ibáñez | Q6: María | R6: 43506427 | S6: 11-5584-7572
A7: AL-006 | B7: Luna | C7: Iván | D7: 42044602 | E7: 11/04/2013 | F7: 1 | G7: A | H7: Mañana | I7: Calle Castro 4189 | J7: 11-6241-8517 | K7: iván.luna@alumnos.ejemplo.edu.ar | L7: Díaz | M7: Benjamín | N7: 32342608 | O7: 11-5020-9830 | P7: Romero | Q7: Delfina | R7: 39807725 | S7: 11-6509-7543
A8: AL-007 | B8: Medina | C8: Valentina | D8: 38279821 | E8: 03/01/2013 | F8: 1 | G8: A | H8: Mañana | I8: Calle Cabrera 998 | J8: 11-4252-3621 | K8: valentina.medina@alumnos.ejemplo.edu.ar | L8: Núñez | M8: Nicolás | N8: 37082668 | O8: 11-7885-2040 | P8: Ruiz | Q8: Emilia | R8: 39997348 | S8: 11-6834-9669
A9: AL-008 | B9: Rojas | C9: María | D9: 42091705 | E9: 04/11/2013 | F9: 1 | G9: A | H9: Mañana | I9: Calle Luna 4498 | J9: 11-5185-6573 | K9: maría.rojas@alumnos.ejemplo.edu.ar | L9: López | M9: Benjamín | N9: 37294150 | O9: 11-4295-8433 | P9: González | Q9: Delfina | R9: 44694373 | S9: 11-5157-9201
A10: AL-009 | B10: Cabrera | C10: Sofía | D10: 40490796 | E10: 10/11/2013 | F10: 1 | G10: A | H10: Mañana | I10: Calle Medina 1729 | J10: 11-4252-7126 | K10: sofía.cabrera@alumnos.ejemplo.edu.ar | L10: Silva | M10: Lucas | N10: 39049278 | O10: 11-7344-1009 | P10: Vega | Q10: Julieta | R10: 38197443 | S10: 11-3159-2832
A11: AL-010 | B11: Núñez | C11: Renata | D11: 35159230 | E11: 08/01/2013 | F11: 1 | G11: A | H11: Mañana | I11: Calle Sánchez 4747 | J11: 11-3645-2403 | K11: renata.núñez@alumnos.ejemplo.edu.ar | L11: Ortiz | M11: Santino | N11: 43690598 | O11: 11-3566-9727 | P11: Silva | Q11: Valentina | R11: 32154051 | S11: 11-6893-3705
A12: AL-011 | B12: Pérez | C12: Emilia | D12: 45584582 | E12: 18/12/2012 | F12: 2 | G12: A | H12: Mañana | I12: Calle Molina 1747 | J12: 11-5553-7537 | K12: emilia.pérez@alumnos.ejemplo.edu.ar | L12: Rojas | M12: Nicolás | N12: 36264956 | O12: 11-6588-9479 | P12: Acosta | Q12: Sofía | R12: 34159166 | S12: 11-4840-2049
A13: AL-012 | B13: Aguirre | C13: Camila | D13: 33694634 | E13: 01/02/2012 | F13: 2 | G13: A | H13: Mañana | I13: Calle Molina 582 | J13: 11-4875-2104 | K13: camila.aguirre@alumnos.ejemplo.edu.ar | L13: Luna | M13: Juan | N13: 44422288 | O13: 11-5706-2160 | P13: Medina | Q13: Camila | R13: 34672073 | S13: 11-6976-4510
A14: AL-013 | B14: Aguirre | C14: Guadalupe | D14: 39667227 | E14: 16/04/2012 | F14: 2 | G14: A | H14: Mañana | I14: Calle Núñez 3974 | J14: 11-6334-4119 | K14: guadalupe.aguirre@alumnos.ejemplo.edu.ar | L14: López | M14: Mateo | N14: 41055895 | O14: 11-6531-6804 | P14: Flores | Q14: Emilia | R14: 37835373 | S14: 11-3443-2612 | T14: Ortiz | U14: Nicolás | V14: 43431713 | W14: 11-3895-5073
A15: AL-014 | B15: Acosta | C15: Bruno | D15: 32351868 | E15: 14/03/2012 | F15: 2 | G15: A | H15: Mañana | I15: Calle Romero 3889 | J15: 11-5046-2235 | K15: bruno.acosta@alumnos.ejemplo.edu.ar | L15: Acosta | M15: Agustín | N15: 44451039 | O15: 11-7508-2604 | P15: Rodríguez | Q15: Pilar | R15: 39069560 | S15: 11-3120-2528
A16: AL-015 | B16: Flores | C16: Valentina | D16: 38147706 | E16: 16/04/2012 | F16: 2 | G16: A | H16: Mañana | I16: Calle Cabrera 3385 | J16: 11-3480-3697 | K16: valentina.flores@alumnos.ejemplo.edu.ar | L16: Ruiz | M16: Juan | N16: 36550190 | O16: 11-5172-8454 | P16: Suárez | Q16: Emilia | R16: 41686866 | S16: 11-7552-8973
A17: AL-016 | B17: Aguirre | C17: Juan | D17: 42343621 | E17: 18/01/2012 | F17: 2 | G17: A | H17: Mañana | I17: Calle Ortiz 2669 | J17: 11-3468-1821 | K17: juan.aguirre@alumnos.ejemplo.edu.ar | L17: Aguirre | M17: Santino | N17: 38436429 | O17: 11-7350-3579 | P17: Rodríguez | Q17: Milagros | R17: 31344047 | S17: 11-4522-2122
A18: AL-017 | B18: Ruiz | C18: Camila | D18: 32011363 | E18: 19/04/2012 | F18: 2 | G18: A | H18: Mañana | I18: Calle Aguirre 4970 | J18: 11-3325-2343 | K18: camila.ruiz@alumnos.ejemplo.edu.ar | L18: Flores | M18: Nicolás | N18: 39792396 | O18: 11-7630-9565 | P18: Álvarez | Q18: Guadalupe | R18: 34374922 | S18: 11-4673-6147
A19: AL-018 | B19: Castro | C19: Nicolás | D19: 35033115 | E19: 15/06/2012 | F19: 2 | G19: A | H19: Mañana | I19: Calle Peralta 694 | J19: 11-3076-8508 | K19: nicolás.castro@alumnos.ejemplo.edu.ar | L19: Vega | M19: Iván | N19: 31677407 | O19: 11-3600-9808 | P19: Pérez | Q19: Milagros | R19: 34449324 | S19: 11-4085-6718
A20: AL-019 | B20: Suárez | C20: Julieta | D20: 32646552 | E20: 15/09/2012 | F20: 2 | G20: A | H20: Mañana | I20: Calle Molina 2578 | J20: 11-7333-1128 | K20: julieta.suárez@alumnos.ejemplo.edu.ar | L20: Rojas | M20: Ramiro | N20: 39304682 | O20: 11-5452-2697 | P20: Luna | Q20: Valentina | R20: 34437001 | S20: 11-3945-2753
A21: AL-020 | B21: Vega | C21: Benjamín | D21: 33533779 | E21: 23/06/2012 | F21: 2 | G21: A | H21: Mañana | I21: Calle Pérez 2262 | J21: 11-7140-9004 | K21: benjamín.vega@alumnos.ejemplo.edu.ar | L21: Romero | M21: Ezequiel | N21: 45236380 | O21: 11-3416-2512 | P21: Castro | Q21: Emilia | R21: 43914152 | S21: 11-5266-1722 | T21: Silva | U21: Benjamín | V21: 40688988 | W21: 11-5145-3647
A22: AL-021 | B22: Molina | C22: Milagros | D22: 37175395 | E22: 18/01/2011 | F22: 3 | G22: A | H22: Tarde | I22: Calle López 716 | J22: 11-4221-9938 | K22: milagros.molina@alumnos.ejemplo.edu.ar | L22: Rodríguez | M22: Ramiro | N22: 36194416 | O22: 11-7771-3426 | P22: Flores | Q22: Valentina | R22: 30701771 | S22: 11-5525-6974
A23: AL-022 | B23: Rodríguez | C23: Renata | D23: 45081452 | E23: 12/04/2011 | F23: 3 | G23: A | H23: Tarde | I23: Calle Rojas 2144 | J23: 11-3842-6794 | K23: renata.rodríguez@alumnos.ejemplo.edu.ar | L23: Silva | M23: Bruno | N23: 44833318 | O23: 11-6329-3532 | P23: Peralta | Q23: Guadalupe | R23: 33971793 | S23: 11-4331-3900
A24: AL-023 | B24: Peralta | C24: Franco | D24: 35573147 | E24: 26/07/2011 | F24: 3 | G24: A | H24: Tarde | I24: Calle Núñez 2132 | J24: 11-5185-3608 | K24: franco.peralta@alumnos.ejemplo.edu.ar | L24: Núñez | M24: Franco | N24: 31813543 | O24: 11-6133-1634 | P24: Cabrera | Q24: Catalina | R24: 33731818 | S24: 11-4634-8541
A25: AL-024 | B25: Sánchez | C25: Renata | D25: 33740036 | E25: 01/11/2011 | F25: 3 | G25: A | H25: Tarde | I25: Calle Pérez 3364 | J25: 11-5689-5564 | K25: renata.sánchez@alumnos.ejemplo.edu.ar | L25: Cabrera | M25: Mateo | N25: 42974268 | O25: 11-5286-6753 | P25: Castro | Q25: Milagros | R25: 36705490 | S25: 11-7392-6425
A26: AL-025 | B26: Martínez | C26: Benjamín | D26: 39740679 | E26: 09/01/2011 | F26: 3 | G26: A | H26: Tarde | I26: Calle López 4987 | J26: 11-6559-6663 | K26: benjamín.martínez@alumnos.ejemplo.edu.ar | L26: Ortiz | M26: Agustín | N26: 35262632 | O26: 11-6574-9379 | P26: López | Q26: Emilia | R26: 45091185 | S26: 11-7723-4114
A27: AL-026 | B27: Medina | C27: María | D27: 45528574 | E27: 26/09/2011 | F27: 3 | G27: A | H27: Tarde | I27: Calle Rojas 1714 | J27: 11-5983-8066 | K27: maría.medina@alumnos.ejemplo.edu.ar | L27: Fernández | M27: Nicolás | N27: 45447971 | O27: 11-5704-6143 | P27: Rojas | Q27: Renata | R27: 32090865 | S27: 11-5460-9308
A28: AL-027 | B28: Molina | C28: Facundo | D28: 34960271 | E28: 18/03/2011 | F28: 3 | G28: A | H28: Tarde | I28: Calle Pérez 3544 | J28: 11-6105-3851 | K28: facundo.molina@alumnos.ejemplo.edu.ar | L28: Vega | M28: Iván | N28: 35049101 | O28: 11-6326-9977 | P28: Ibáñez | Q28: María | R28: 35098175 | S28: 11-5350-4443
A29: AL-028 | B29: Álvarez | C29: Pilar | D29: 37801207 | E29: 15/08/2011 | F29: 3 | G29: A | H29: Tarde | I29: Calle Rojas 1850 | J29: 11-7187-8752 | K29: pilar.álvarez@alumnos.ejemplo.edu.ar | L29: Núñez | M29: Ezequiel | N29: 43355079 | O29: 11-4390-2389 | P29: Suárez | Q29: Milagros | R29: 41137619 | S29: 11-5745-2530
A30: AL-029 | B30: Suárez | C30: Pilar | D30: 33768844 | E30: 26/04/2011 | F30: 3 | G30: A | H30: Tarde | I30: Calle Díaz 300 | J30: 11-3378-5011 | K30: pilar.suárez@alumnos.ejemplo.edu.ar | L30: Benítez | M30: Iván | N30: 44256232 | O30: 11-3596-8461 | P30: Flores | Q30: Guadalupe | R30: 40565709 | S30: 11-7715-4185
A31: AL-030 | B31: Sánchez | C31: Facundo | D31: 32475836 | E31: 21/12/2011 | F31: 3 | G31: A | H31: Tarde | I31: Calle González 973 | J31: 11-6482-4585 | K31: facundo.sánchez@alumnos.ejemplo.edu.ar | L31: Martínez | M31: Agustín | N31: 41675462 | O31: 11-7243-8611 | P31: Rodríguez | Q31: Milagros | R31: 34180853 | S31: 11-3994-8478 | T31: Acosta | U31: Emilia | V31: 38910914 | W31: 11-7578-6198

Sheet Profesores
A1: ID_Profesor | B1: Apellido | C1: Nombre | D1: DNI | E1: Teléfono | F1: Email | G1: Materia_Principal | H1: Cursos_Asignados
A2: PR-01 | B2: Gómez | C2: Laura | D2: 45939019 | E2: 11-6625-9270 | F2: laura.gómez@colegio.ejemplo.edu.ar | G2: Lengua y Literatura | H2: 1°A (Mañana), 2°A (Mañana), 3°A (Tarde)
A3: PR-02 | B3: Fernández | C3: Marcelo | D3: 37159521 | E3: 11-7488-8305 | F3: marcelo.fernández@colegio.ejemplo.edu.ar | G3: Matemática | H3: 1°A (Mañana), 2°A (Mañana), 3°A (Tarde)
A4: PR-03 | B4: Rodríguez | C4: Ana | D4: 45052654 | E4: 11-4303-8777 | F4: ana.rodríguez@colegio.ejemplo.edu.ar | G4: Historia | H4: 1°A (Mañana), 2°A (Mañana), 3°A (Tarde)
A5: PR-04 | B5: Pérez | C5: Diego | D5: 37550917 | E5: 11-5123-5050 | F5: diego.pérez@colegio.ejemplo.edu.ar | G5: Geografía | H5: 1°A (Mañana), 2°A (Mañana), 3°A (Tarde)
A6: PR-05 | B6: López | C6: Carla | D6: 44090561 | E6: 11-5271-9540 | F6: carla.lópez@colegio.ejemplo.edu.ar | G6: Biología | H6: 1°A (Mañana), 3°A (Tarde)
A7: PR-06 | B7: Martínez | C7: Julián | D7: 38130188 | E7: 11-4959-5499 | F7: julián.martínez@colegio.ejemplo.edu.ar | G7: Inglés | H7: 1°A (Mañana), 2°A (Mañana), 3°A (Tarde)
A8: PR-07 | B8: Sánchez | C8: Pablo | D8: 37379837 | E8: 11-3634-5681 | F8: pablo.sánchez@colegio.ejemplo.edu.ar | G8: Educación Física | H8: 1°A (Mañana), 2°A (Mañana), 3°A (Tarde)
A9: PR-08 | B9: Torres | C9: Marina | D9: 33934149 | E9: 11-5225-6502 | F9: marina.torres@colegio.ejemplo.edu.ar | G9: Educación Artística | H9: 1°A (Mañana)
A10: PR-09 | B10: Ramírez | C10: Gustavo | D10: 35363836 | E10: 11-7424-2320 | F10: gustavo.ramírez@colegio.ejemplo.edu.ar | G10: Física-Química | H10: 2°A (Mañana)
A11: PR-10 | B11: Flores | C11: Verónica | D11: 32321531 | E11: 11-4235-4788 | F11: verónica.flores@colegio.ejemplo.edu.ar | G11: Formación Ética y Ciudadana | H11: 2°A (Mañana)
A12: PR-11 | B12: Acosta | C12: Sebastián | D12: 36426265 | E12: 11-4251-4505 | F12: sebastián.acosta@colegio.ejemplo.edu.ar | G12: Tecnología | H12: 3°A (Tarde)

Sheet Plan_Materias
A1: Año | B1: División | C1: Turno | D1: Materia | E1: ID_Profesor | F1: Profesor_Asignado | G1: Cant._Alumnos_del_Curso
A2: 1 | B2: A | C2: Mañana | D2: Lengua y Literatura | E2: PR-01 | F2: =IFERROR(INDEX(Profesores!$B$2:$B$12,MATCH($E2,Profesores!$A$2:$A$12,0))&" "&INDEX(Profesores!$C$2:$C$12,MATCH($E2,Profesores!$A$2:$A$12,0)),"") -> Gómez Laura | G2: =COUNTIFS(Alumnos!$F$2:$F$31,$A2,Alumnos!$G$2:$G$31,$B2) -> 10
A3: 1 | B3: A | C3: Mañana | D3: Matemática | E3: PR-02 | F3: =IFERROR(INDEX(Profesores!$B$2:$B$12,MATCH($E3,Profesores!$A$2:$A$12,0))&" "&INDEX(Profesores!$C$2:$C$12,MATCH($E3,Profesores!$A$2:$A$12,0)),"") -> Fernández Marcelo | G3: =COUNTIFS(Alumnos!$F$2:$F$31,$A3,Alumnos!$G$2:$G$31,$B3) -> 10
A4: 1 | B4: A | C4: Mañana | D4: Historia | E4: PR-03 | F4: =IFERROR(INDEX(Profesores!$B$2:$B$12,MATCH($E4,Profesores!$A$2:$A$12,0))&" "&INDEX(Profesores!$C$2:$C$12,MATCH($E4,Profesores!$A$2:$A$12,0)),"") -> Rodríguez Ana | G4: =COUNTIFS(Alumnos!$F$2:$F$31,$A4,Alumnos!$G$2:$G$31,$B4) -> 10
A5: 1 | B5: A | C5: Mañana | D5: Geografía | E5: PR-04 | F5: =IFERROR(INDEX(Profesores!$B$2:$B$12,MATCH($E5,Profesores!$A$2:$A$12,0))&" "&INDEX(Profesores!$C$2:$C$12,MATCH($E5,Profesores!$A$2:$A$12,0)),"") -> Pérez Diego | G5: =COUNTIFS(Alumnos!$F$2:$F$31,$A5,Alumnos!$G$2:$G$31,$B5) -> 10
A6: 1 | B6: A | C6: Mañana | D6: Biología | E6: PR-05 | F6: =IFERROR(INDEX(Profesores!$B$2:$B$12,MATCH($E6,Profesores!$A$2:$A$12,0))&" "&INDEX(Profesores!$C$2:$C$12,MATCH($E6,Profesores!$A$2:$A$12,0)),"") -> López Carla | G6: =COUNTIFS(Alumnos!$F$2:$F$31,$A6,Alumnos!$G$2:$G$31,$B6) -> 10
A7: 1 | B7: A | C7: Mañana | D7: Inglés | E7: PR-06 | F7: =IFERROR(INDEX(Profesores!$B$2:$B$12,MATCH($E7,Profesores!$A$2:$A$12,0))&" "&INDEX(Profesores!$C$2:$C$12,MATCH($E7,Profesores!$A$2:$A$12,0)),"") -> Martínez Julián | G7: =COUNTIFS(Alumnos!$F$2:$F$31,$A7,Alumnos!$G$2:$G$31,$B7) -> 10
A8: 1 | B8: A | C8: Mañana | D8: Educación Física | E8: PR-07 | F8: =IFERROR(INDEX(Profesores!$B$2:$B$12,MATCH($E8,Profesores!$A$2:$A$12,0))&" "&INDEX(Profesores!$C$2:$C$12,MATCH($E8,Profesores!$A$2:$A$12,0)),"") -> Sánchez Pablo | G8: =COUNTIFS(Alumnos!$F$2:$F$31,$A8,Alumnos!$G$2:$G$31,$B8) -> 10
A9: 1 | B9: A | C9: Mañana | D9: Educación Artística | E9: PR-08 | F9: =IFERROR(INDEX(Profesores!$B$2:$B$12,MATCH($E9,Profesores!$A$2:$A$12,0))&" "&INDEX(Profesores!$C$2:$C$12,MATCH($E9,Profesores!$A$2:$A$12,0)),"") -> Torres Marina | G9: =COUNTIFS(Alumnos!$F$2:$F$31,$A9,Alumnos!$G$2:$G$31,$B9) -> 10
A10: 2 | B10: A | C10: Mañana | D10: Lengua y Literatura | E10: PR-01 | F10: =IFERROR(INDEX(Profesores!$B$2:$B$12,MATCH($E10,Profesores!$A$2:$A$12,0))&" "&INDEX(Profesores!$C$2:$C$12,MATCH($E10,Profesores!$A$2:$A$12,0)),"") -> Gómez Laura | G10: =COUNTIFS(Alumnos!$F$2:$F$31,$A10,Alumnos!$G$2:$G$31,$B10) -> 10
A11: 2 | B11: A | C11: Mañana | D11: Matemática | E11: PR-02 | F11: =IFERROR(INDEX(Profesores!$B$2:$B$12,MATCH($E11,Profesores!$A$2:$A$12,0))&" "&INDEX(Profesores!$C$2:$C$12,MATCH($E11,Profesores!$A$2:$A$12,0)),"") -> Fernández Marcelo | G11: =COUNTIFS(Alumnos!$F$2:$F$31,$A11,Alumnos!$G$2:$G$31,$B11) -> 10
A12: 2 | B12: A | C12: Mañana | D12: Historia | E12: PR-03 | F12: =IFERROR(INDEX(Profesores!$B$2:$B$12,MATCH($E12,Profesores!$A$2:$A$12,0))&" "&INDEX(Profesores!$C$2:$C$12,MATCH($E12,Profesores!$A$2:$A$12,0)),"") -> Rodríguez Ana | G12: =COUNTIFS(Alumnos!$F$2:$F$31,$A12,Alumnos!$G$2:$G$31,$B12) -> 10
A13: 2 | B13: A | C13: Mañana | D13: Geografía | E13: PR-04 | F13: =IFERROR(INDEX(Profesores!$B$2:$B$12,MATCH($E13,Profesores!$A$2:$A$12,0))&" "&INDEX(Profesores!$C$2:$C$12,MATCH($E13,Profesores!$A$2:$A$12,0)),"") -> Pérez Diego | G13: =COUNTIFS(Alumnos!$F$2:$F$31,$A13,Alumnos!$G$2:$G$31,$B13) -> 10
... A25: 3 | B25: A | C25: Tarde | D25: Tecnología | E25: PR-11 | F25: =IFERROR(INDEX(Profesores!$B$2:$B$12,MATCH($E25,Profesores!$A$2:$A$12,0))&" "&INDEX(Profesores!$C$2:$C$12,MATCH($E25,Profesores!$A$2:$A$12,0)),"") -> Acosta Sebastián | G25: =COUNTIFS(Alumnos!$F$2:$F$31,$A25,Alumnos!$G$2:$G$31,$B25) -> 10

Sheet Notas
A1: ID_Alumno | B1: Alumno | C1: Año | D1: División | E1: Materia | F1: ID_Profesor | G1: Profesor | H1: Nota_1er_Trim. | I1: Nota_2do_Trim. | J1: Nota_3er_Trim. | K1: Promedio | L1: Condición | M1: Observación
A2: AL-001 | B2: =IFERROR(INDEX(Alumnos!$B$2:$B$31,MATCH($A2,Alumnos!$A$2:$A$31,0))&", "&INDEX(Alumnos!$C$2:$C$31,MATCH($A2,Alumnos!$A$2:$A$31,0)),"") -> Ortiz, María | C2: 1 | D2: A | E2: Lengua y Literatura | F2: PR-01 | G2: =IFERROR(INDEX(Profesores!$B$2:$B$12,MATCH($F2,Profesores!$A$2:$A$12,0))&" "&INDEX(Profesores!$C$2:$C$12,MATCH($F2,Profesores!$A$2:$A$12,0)),"") -> Gómez Laura | H2: 4 | I2: 7 | J2: 7 | K2: =IFERROR(AVERAGE($H2:$J2),"") -> 6 | L2: =IF($K2="","",IF($K2>=6,"Aprobado","Desaprobado")) -> Aprobado | M2: Buena participación en clase
A3: AL-002 | B3: =IFERROR(INDEX(Alumnos!$B$2:$B$31,MATCH($A3,Alumnos!$A$2:$A$31,0))&", "&INDEX(Alumnos!$C$2:$C$31,MATCH($A3,Alumnos!$A$2:$A$31,0)),"") -> Herrera, Delfina | C3: 1 | D3: A | E3: Lengua y Literatura | F3: PR-01 | G3: =IFERROR(INDEX(Profesores!$B$2:$B$12,MATCH($F3,Profesores!$A$2:$A$12,0))&" "&INDEX(Profesores!$C$2:$C$12,MATCH($F3,Profesores!$A$2:$A$12,0)),"") -> Gómez Laura | H3: 8 | I3: 7 | J3: 7 | K3: =IFERROR(AVERAGE($H3:$J3),"") -> 7.3333333 | L3: =IF($K3="","",IF($K3>=6,"Aprobado","Desaprobado")) -> Aprobado
A4: AL-003 | B4: =IFERROR(INDEX(Alumnos!$B$2:$B$31,MATCH($A4,Alumnos!$A$2:$A$31,0))&", "&INDEX(Alumnos!$C$2:$C$31,MATCH($A4,Alumnos!$A$2:$A$31,0)),"") -> Vega, Joaquín | C4: 1 | D4: A | E4: Lengua y Literatura | F4: PR-01 | G4: =IFERROR(INDEX(Profesores!$B$2:$B$12,MATCH($F4,Profesores!$A$2:$A$12,0))&" "&INDEX(Profesores!$C$2:$C$12,MATCH($F4,Profesores!$A$2:$A$12,0)),"") -> Gómez Laura | H4: 5 | I4: 10 | J4: 7 | K4: =IFERROR(AVERAGE($H4:$J4),"") -> 7.3333333 | L4: =IF($K4="","",IF($K4>=6,"Aprobado","Desaprobado")) -> Aprobado | M4: Entrega tarde los trabajos
A5: AL-004 | B5: =IFERROR(INDEX(Alumnos!$B$2:$B$31,MATCH($A5,Alumnos!$A$2:$A$31,0))&", "&INDEX(Alumnos!$C$2:$C$31,MATCH($A5,Alumnos!$A$2:$A$31,0)),"") -> Silva, Tomás | C5: 1 | D5: A | E5: Lengua y Literatura | F5: PR-01 | G5: =IFERROR(INDEX(Profesores!$B$2:$B$12,MATCH($F5,Profesores!$A$2:$A$12,0))&" "&INDEX(Profesores!$C$2:$C$12,MATCH($F5,Profesores!$A$2:$A$12,0)),"") -> Gómez Laura | H5: 10 | I5: 8 | J5: 9 | K5: =IFERROR(AVERAGE($H5:$J5),"") -> 9 | L5: =IF($K5="","",IF($K5>=6,"Aprobado","Desaprobado")) -> Aprobado
A6: AL-005 | B6: =IFERROR(INDEX(Alumnos!$B$2:$B$31,MATCH($A6,Alumnos!$A$2:$A$31,0))&", "&INDEX(Alumnos!$C$2:$C$31,MATCH($A6,Alumnos!$A$2:$A$31,0)),"") -> Sánchez, Franco | C6: 1 | D6: A | E6: Lengua y Literatura | F6: PR-01 | G6: =IFERROR(INDEX(Profesores!$B$2:$B$12,MATCH($F6,Profesores!$A$2:$A$12,0))&" "&INDEX(Profesores!$C$2:$C$12,MATCH($F6,Profesores!$A$2:$A$12,0)),"") -> Gómez Laura | H6: 10 | I6: 10 | J6: 8 | K6: =IFERROR(AVERAGE($H6:$J6),"") -> 9.3333333 | L6: =IF($K6="","",IF($K6>=6,"Aprobado","Desaprobado")) -> Aprobado | M6: Entrega tarde los trabajos
A7: AL-006 | B7: =IFERROR(INDEX(Alumnos!$B$2:$B$31,MATCH($A7,Alumnos!$A$2:$A$31,0))&", "&INDEX(Alumnos!$C$2:$C$31,MATCH($A7,Alumnos!$A$2:$A$31,0)),"") -> Luna, Iván | C7: 1 | D7: A | E7: Lengua y Literatura | F7: PR-01 | G7: =IFERROR(INDEX(Profesores!$B$2:$B$12,MATCH($F7,Profesores!$A$2:$A$12,0))&" "&INDEX(Profesores!$C$2:$C$12,MATCH($F7,Profesores!$A$2:$A$12,0)),"") -> Gómez Laura | H7: 7 | I7: 4 | J7: 6 | K7: =IFERROR(AVERAGE($H7:$J7),"") -> 5.6666667 | L7: =IF($K7="","",IF($K7>=6,"Aprobado","Desaprobado")) -> Desaprobado | M7: Necesita repasar contenidos previos
A8: AL-007 | B8: =IFERROR(INDEX(Alumnos!$B$2:$B$31,MATCH($A8,Alumnos!$A$2:$A$31,0))&", "&INDEX(Alumnos!$C$2:$C$31,MATCH($A8,Alumnos!$A$2:$A$31,0)),"") -> Medina, Valentina | C8: 1 | D8: A | E8: Lengua y Literatura | F8: PR-01 | G8: =IFERROR(INDEX(Profesores!$B$2:$B$12,MATCH($F8,Profesores!$A$2:$A$12,0))&" "&INDEX(Profesores!$C$2:$C$12,MATCH($F8,Profesores!$A$2:$A$12,0)),"") -> Gómez Laura | H8: 10 | I8: 7 | J8: 10 | K8: =IFERROR(AVERAGE($H8:$J8),"") -> 9 | L8: =IF($K8="","",IF($K8>=6,"Aprobado","Desaprobado")) -> Aprobado | M8: Entrega tarde los trabajos
A9: AL-008 | B9: =IFERROR(INDEX(Alumnos!$B$2:$B$31,MATCH($A9,Alumnos!$A$2:$A$31,0))&", "&INDEX(Alumnos!$C$2:$C$31,MATCH($A9,Alumnos!$A$2:$A$31,0)),"") -> Rojas, María | C9: 1 | D9: A | E9: Lengua y Literatura | F9: PR-01 | G9: =IFERROR(INDEX(Profesores!$B$2:$B$12,MATCH($F9,Profesores!$A$2:$A$12,0))&" "&INDEX(Profesores!$C$2:$C$12,MATCH($F9,Profesores!$A$2:$A$12,0)),"") -> Gómez Laura | H9: 8 | I9: 9 | J9: 9 | K9: =IFERROR(AVERAGE($H9:$J9),"") -> 8.6666667 | L9: =IF($K9="","",IF($K9>=6,"Aprobado","Desaprobado")) -> Aprobado | M9: Recomendado apoyo escolar
A10: AL-009 | B10: =IFERROR(INDEX(Alumnos!$B$2:$B$31,MATCH($A10,Alumnos!$A$2:$A$31,0))&", "&INDEX(Alumnos!$C$2:$C$31,MATCH($A10,Alumnos!$A$2:$A$31,0)),"") -> Cabrera, Sofía | C10: 1 | D10: A | E10: Lengua y Literatura | F10: PR-01 | G10: =IFERROR(INDEX(Profesores!$B$2:$B$12,MATCH($F10,Profesores!$A$2:$A$12,0))&" "&INDEX(Profesores!$C$2:$C$12,MATCH($F10,Profesores!$A$2:$A$12,0)),"") -> Gómez Laura | H10: 10 | I10: 8 | J10: 5 | K10: =IFERROR(AVERAGE($H10:$J10),"") -> 7.6666667 | L10: =IF($K10="","",IF($K10>=6,"Aprobado","Desaprobado")) -> Aprobado | M10: Excelente evolución
A11: AL-010 | B11: =IFERROR(INDEX(Alumnos!$B$2:$B$31,MATCH($A11,Alumnos!$A$2:$A$31,0))&", "&INDEX(Alumnos!$C$2:$C$31,MATCH($A11,Alumnos!$A$2:$A$31,0)),"") -> Núñez, Renata | C11: 1 | D11: A | E11: Lengua y Literatura | F11: PR-01 | G11: =IFERROR(INDEX(Profesores!$B$2:$B$12,MATCH($F11,Profesores!$A$2:$A$12,0))&" "&INDEX(Profesores!$C$2:$C$12,MATCH($F11,Profesores!$A$2:$A$12,0)),"") -> Gómez Laura | H11: 5 | I11: 6 | J11: 7 | K11: =IFERROR(AVERAGE($H11:$J11),"") -> 6 | L11: =IF($K11="","",IF($K11>=6,"Aprobado","Desaprobado")) -> Aprobado | M11: Excelente evolución
A12: AL-001 | B12: =IFERROR(INDEX(Alumnos!$B$2:$B$31,MATCH($A12,Alumnos!$A$2:$A$31,0))&", "&INDEX(Alumnos!$C$2:$C$31,MATCH($A12,Alumnos!$A$2:$A$31,0)),"") -> Ortiz, María | C12: 1 | D12: A | E12: Matemática | F12: PR-02 | G12: =IFERROR(INDEX(Profesores!$B$2:$B$12,MATCH($F12,Profesores!$A$2:$A$12,0))&" "&INDEX(Profesores!$C$2:$C$12,MATCH($F12,Profesores!$A$2:$A$12,0)),"") -> Fernández Marcelo | H12: 4 | I12: 7 | J12: 6 | K12: =IFERROR(AVERAGE($H12:$J12),"") -> 5.6666667 | L12: =IF($K12="","",IF($K12>=6,"Aprobado","Desaprobado")) -> Desaprobado | M12: Entrega tarde los trabajos
A13: AL-002 | B13: =IFERROR(INDEX(Alumnos!$B$2:$B$31,MATCH($A13,Alumnos!$A$2:$A$31,0))&", "&INDEX(Alumnos!$C$2:$C$31,MATCH($A13,Alumnos!$A$2:$A$31,0)),"") -> Herrera, Delfina | C13: 1 | D13: A | E13: Matemática | F13: PR-02 | G13: =IFERROR(INDEX(Profesores!$B$2:$B$12,MATCH($F13,Profesores!$A$2:$A$12,0))&" "&INDEX(Profesores!$C$2:$C$12,MATCH($F13,Profesores!$A$2:$A$12,0)),"") -> Fernández Marcelo | H13: 9 | I13: 5 | J13: 10 | K13: =IFERROR(AVERAGE($H13:$J13),"") -> 8 | L13: =IF($K13="","",IF($K13>=6,"Aprobado","Desaprobado")) -> Aprobado | M13: Excelente evolución
A14: AL-003 | B14: =IFERROR(INDEX(Alumnos!$B$2:$B$31,MATCH($A14,Alumnos!$A$2:$A$31,0))&", "&INDEX(Alumnos!$C$2:$C$31,MATCH($A14,Alumnos!$A$2:$A$31,0)),"") -> Vega, Joaquín | C14: 1 | D14: A | E14: Matemática | F14: PR-02 | G14: =IFERROR(INDEX(Profesores!$B$2:$B$12,MATCH($F14,Profesores!$A$2:$A$12,0))&" "&INDEX(Profesores!$C$2:$C$12,MATCH($F14,Profesores!$A$2:$A$12,0)),"") -> Fernández Marcelo | H14: 5 | I14: 8 | J14: 8 | K14: =IFERROR(AVERAGE($H14:$J14),"") -> 7 | L14: =IF($K14="","",IF($K14>=6,"Aprobado","Desaprobado")) -> Aprobado
A15: AL-004 | B15: =IFERROR(INDEX(Alumnos!$B$2:$B$31,MATCH($A15,Alumnos!$A$2:$A$31,0))&", "&INDEX(Alumnos!$C$2:$C$31,MATCH($A15,Alumnos!$A$2:$A$31,0)),"") -> Silva, Tomás | C15: 1 | D15: A | E15: Matemática | F15: PR-02 | G15: =IFERROR(INDEX(Profesores!$B$2:$B$12,MATCH($F15,Profesores!$A$2:$A$12,0))&" "&INDEX(Profesores!$C$2:$C$12,MATCH($F15,Profesores!$A$2:$A$12,0)),"") -> Fernández Marcelo | H15: 7 | I15: 8 | J15: 8 | K15: =IFERROR(AVERAGE($H15:$J15),"") -> 7.6666667 | L15: =IF($K15="","",IF($K15>=6,"Aprobado","Desaprobado")) -> Aprobado
A16: AL-005 | B16: =IFERROR(INDEX(Alumnos!$B$2:$B$31,MATCH($A16,Alumnos!$A$2:$A$31,0))&", "&INDEX(Alumnos!$C$2:$C$31,MATCH($A16,Alumnos!$A$2:$A$31,0)),"") -> Sánchez, Franco | C16: 1 | D16: A | E16: Matemática | F16: PR-02 | G16: =IFERROR(INDEX(Profesores!$B$2:$B$12,MATCH($F16,Profesores!$A$2:$A$12,0))&" "&INDEX(Profesores!$C$2:$C$12,MATCH($F16,Profesores!$A$2:$A$12,0)),"") -> Fernández Marcelo | H16: 4 | I16: 9 | J16: 7 | K16: =IFERROR(AVERAGE($H16:$J16),"") -> 6.6666667 | L16: =IF($K16="","",IF($K16>=6,"Aprobado","Desaprobado")) -> Aprobado
A17: AL-006 | B17: =IFERROR(INDEX(Alumnos!$B$2:$B$31,MATCH($A17,Alumnos!$A$2:$A$31,0))&", "&INDEX(Alumnos!$C$2:$C$31,MATCH($A17,Alumnos!$A$2:$A$31,0)),"") -> Luna, Iván | C17: 1 | D17: A | E17: Matemática | F17: PR-02 | G17: =IFERROR(INDEX(Profesores!$B$2:$B$12,MATCH($F17,Profesores!$A$2:$A$12,0))&" "&INDEX(Profesores!$C$2:$C$12,MATCH($F17,Profesores!$A$2:$A$12,0)),"") -> Fernández Marcelo | H17: 10 | I17: 7 | J17: 5 | K17: =IFERROR(AVERAGE($H17:$J17),"") -> 7.3333333 | L17: =IF($K17="","",IF($K17>=6,"Aprobado","Desaprobado")) -> Aprobado
A18: AL-007 | B18: =IFERROR(INDEX(Alumnos!$B$2:$B$31,MATCH($A18,Alumnos!$A$2:$A$31,0))&", "&INDEX(Alumnos!$C$2:$C$31,MATCH($A18,Alumnos!$A$2:$A$31,0)),"") -> Medina, Valentina | C18: 1 | D18: A | E18: Matemática | F18: PR-02 | G18: =IFERROR(INDEX(Profesores!$B$2:$B$12,MATCH($F18,Profesores!$A$2:$A$12,0))&" "&INDEX(Profesores!$C$2:$C$12,MATCH($F18,Profesores!$A$2:$A$12,0)),"") -> Fernández Marcelo | H18: 6 | I18: 7 | J18: 6 | K18: =IFERROR(AVERAGE($H18:$J18),"") -> 6.3333333 | L18: =IF($K18="","",IF($K18>=6,"Aprobado","Desaprobado")) -> Aprobado | M18: Muy buen desempeño
A19: AL-008 | B19: =IFERROR(INDEX(Alumnos!$B$2:$B$31,MATCH($A19,Alumnos!$A$2:$A$31,0))&", "&INDEX(Alumnos!$C$2:$C$31,MATCH($A19,Alumnos!$A$2:$A$31,0)),"") -> Rojas, María | C19: 1 | D19: A | E19: Matemática | F19: PR-02 | G19: =IFERROR(INDEX(Profesores!$B$2:$B$12,MATCH($F19,Profesores!$A$2:$A$12,0))&" "&INDEX(Profesores!$C$2:$C$12,MATCH($F19,Profesores!$A$2:$A$12,0)),"") -> Fernández Marcelo | H19: 7 | I19: 6 | J19: 6 | K19: =IFERROR(AVERAGE($H19:$J19),"") -> 6.3333333 | L19: =IF($K19="","",IF($K19>=6,"Aprobado","Desaprobado")) -> Aprobado | M19: Entrega tarde los trabajos
A20: AL-009 | B20: =IFERROR(INDEX(Alumnos!$B$2:$B$31,MATCH($A20,Alumnos!$A$2:$A$31,0))&", "&INDEX(Alumnos!$C$2:$C$31,MATCH($A20,Alumnos!$A$2:$A$31,0)),"") -> Cabrera, Sofía | C20: 1 | D20: A | E20: Matemática | F20: PR-02 | G20: =IFERROR(INDEX(Profesores!$B$2:$B$12,MATCH($F20,Profesores!$A$2:$A$12,0))&" "&INDEX(Profesores!$C$2:$C$12,MATCH($F20,Profesores!$A$2:$A$12,0)),"") -> Fernández Marcelo | H20: 6 | I20: 10 | J20: 10 | K20: =IFERROR(AVERAGE($H20:$J20),"") -> 8.6666667 | L20: =IF($K20="","",IF($K20>=6,"Aprobado","Desaprobado")) -> Aprobado | M20: Entrega tarde los trabajos
A21: AL-010 | B21: =IFERROR(INDEX(Alumnos!$B$2:$B$31,MATCH($A21,Alumnos!$A$2:$A$31,0))&", "&INDEX(Alumnos!$C$2:$C$31,MATCH($A21,Alumnos!$A$2:$A$31,0)),"") -> Núñez, Renata | C21: 1 | D21: A | E21: Matemática | F21: PR-02 | G21: =IFERROR(INDEX(Profesores!$B$2:$B$12,MATCH($F21,Profesores!$A$2:$A$12,0))&" "&INDEX(Profesores!$C$2:$C$12,MATCH($F21,Profesores!$A$2:$A$12,0)),"") -> Fernández Marcelo | H21: 6 | I21: 10 | J21: 4 | K21: =IFERROR(AVERAGE($H21:$J21),"") -> 6.6666667 | L21: =IF($K21="","",IF($K21>=6,"Aprobado","Desaprobado")) -> Aprobado | M21: Excelente evolución
A22: AL-001 | B22: =IFERROR(INDEX(Alumnos!$B$2:$B$31,MATCH($A22,Alumnos!$A$2:$A$31,0))&", "&INDEX(Alumnos!$C$2:$C$31,MATCH($A22,Alumnos!$A$2:$A$31,0)),"") -> Ortiz, María | C22: 1 | D22: A | E22: Historia | F22: PR-03 | G22: =IFERROR(INDEX(Profesores!$B$2:$B$12,MATCH($F22,Profesores!$A$2:$A$12,0))&" "&INDEX(Profesores!$C$2:$C$12,MATCH($F22,Profesores!$A$2:$A$12,0)),"") -> Rodríguez Ana | H22: 4 | I22: 9 | J22: 8 | K22: =IFERROR(AVERAGE($H22:$J22),"") -> 7 | L22: =IF($K22="","",IF($K22>=6,"Aprobado","Desaprobado")) -> Aprobado
A23: AL-002 | B23: =IFERROR(INDEX(Alumnos!$B$2:$B$31,MATCH($A23,Alumnos!$A$2:$A$31,0))&", "&INDEX(Alumnos!$C$2:$C$31,MATCH($A23,Alumnos!$A$2:$A$31,0)),"") -> Herrera, Delfina | C23: 1 | D23: A | E23: Historia | F23: PR-03 | G23: =IFERROR(INDEX(Profesores!$B$2:$B$12,MATCH($F23,Profesores!$A$2:$A$12,0))&" "&INDEX(Profesores!$C$2:$C$12,MATCH($F23,Profesores!$A$2:$A$12,0)),"") -> Rodríguez Ana | H23: 6 | I23: 5 | J23: 9 | K23: =IFERROR(AVERAGE($H23:$J23),"") -> 6.6666667 | L23: =IF($K23="","",IF($K23>=6,"Aprobado","Desaprobado")) -> Aprobado
A24: AL-003 | B24: =IFERROR(INDEX(Alumnos!$B$2:$B$31,MATCH($A24,Alumnos!$A$2:$A$31,0))&", "&INDEX(Alumnos!$C$2:$C$31,MATCH($A24,Alumnos!$A$2:$A$31,0)),"") -> Vega, Joaquín | C24: 1 | D24: A | E24: Historia | F24: PR-03 | G24: =IFERROR(INDEX(Profesores!$B$2:$B$12,MATCH($F24,Profesores!$A$2:$A$12,0))&" "&INDEX(Profesores!$C$2:$C$12,MATCH($F24,Profesores!$A$2:$A$12,0)),"") -> Rodríguez Ana | H24: 10 | I24: 9 | J24: 4 | K24: =IFERROR(AVERAGE($H24:$J24),"") -> 7.6666667 | L24: =IF($K24="","",IF($K24>=6,"Aprobado","Desaprobado")) -> Aprobado
A25: AL-004 | B25: =IFERROR(INDEX(Alumnos!$B$2:$B$31,MATCH($A25,Alumnos!$A$2:$A$31,0))&", "&INDEX(Alumnos!$C$2:$C$31,MATCH($A25,Alumnos!$A$2:$A$31,0)),"") -> Silva, Tomás | C25: 1 | D25: A | E25: Historia | F25: PR-03 | G25: =IFERROR(INDEX(Profesores!$B$2:$B$12,MATCH($F25,Profesores!$A$2:$A$12,0))&" "&INDEX(Profesores!$C$2:$C$12,MATCH($F25,Profesores!$A$2:$A$12,0)),"") -> Rodríguez Ana | H25: 5 | I25: 5 | J25: 10 | K25: =IFERROR(AVERAGE($H25:$J25),"") -> 6.6666667 | L25: =IF($K25="","",IF($K25>=6,"Aprobado","Desaprobado")) -> Aprobado
A26: AL-005 | B26: =IFERROR(INDEX(Alumnos!$B$2:$B$31,MATCH($A26,Alumnos!$A$2:$A$31,0))&", "&INDEX(Alumnos!$C$2:$C$31,MATCH($A26,Alumnos!$A$2:$A$31,0)),"") -> Sánchez, Franco | C26: 1 | D26: A | E26: Historia | F26: PR-03 | G26: =IFERROR(INDEX(Profesores!$B$2:$B$12,MATCH($F26,Profesores!$A$2:$A$12,0))&" "&INDEX(Profesores!$C$2:$C$12,MATCH($F26,Profesores!$A$2:$A$12,0)),"") -> Rodríguez Ana | H26: 8 | I26: 5 | J26: 5 | K26: =IFERROR(AVERAGE($H26:$J26),"") -> 6 | L26: =IF($K26="","",IF($K26>=6,"Aprobado","Desaprobado")) -> Aprobado
A27: AL-006 | B27: =IFERROR(INDEX(Alumnos!$B$2:$B$31,MATCH($A27,Alumnos!$A$2:$A$31,0))&", "&INDEX(Alumnos!$C$2:$C$31,MATCH($A27,Alumnos!$A$2:$A$31,0)),"") -> Luna, Iván | C27: 1 | D27: A | E27: Historia | F27: PR-03 | G27: =IFERROR(INDEX(Profesores!$B$2:$B$12,MATCH($F27,Profesores!$A$2:$A$12,0))&" "&INDEX(Profesores!$C$2:$C$12,MATCH($F27,Profesores!$A$2:$A$12,0)),"") -> Rodríguez Ana | H27: 7 | I27: 9 | J27: 4 | K27: =IFERROR(AVERAGE($H27:$J27),"") -> 6.6666667 | L27: =IF($K27="","",IF($K27>=6,"Aprobado","Desaprobado")) -> Aprobado | M27: Cumple con lo solicitado
A28: AL-007 | B28: =IFERROR(INDEX(Alumnos!$B$2:$B$31,MATCH($A28,Alumnos!$A$2:$A$31,0))&", "&INDEX(Alumnos!$C$2:$C$31,MATCH($A28,Alumnos!$A$2:$A$31,0)),"") -> Medina, Valentina | C28: 1 | D28: A | E28: Historia | F28: PR-03 | G28: =IFERROR(INDEX(Profesores!$B$2:$B$12,MATCH($F28,Profesores!$A$2:$A$12,0))&" "&INDEX(Profesores!$C$2:$C$12,MATCH($F28,Profesores!$A$2:$A$12,0)),"") -> Rodríguez Ana | H28: 5 | I28: 7 | J28: 9 | K28: =IFERROR(AVERAGE($H28:$J28),"") -> 7 | L28: =IF($K28="","",IF($K28>=6,"Aprobado","Desaprobado")) -> Aprobado | M28: Necesita repasar contenidos previos
A29: AL-008 | B29: =IFERROR(INDEX(Alumnos!$B$2:$B$31,MATCH($A29,Alumnos!$A$2:$A$31,0))&", "&INDEX(Alumnos!$C$2:$C$31,MATCH($A29,Alumnos!$A$2:$A$31,0)),"") -> Rojas, María | C29: 1 | D29: A | E29: Historia | F29: PR-03 | G29: =IFERROR(INDEX(Profesores!$B$2:$B$12,MATCH($F29,Profesores!$A$2:$A$12,0))&" "&INDEX(Profesores!$C$2:$C$12,MATCH($F29,Profesores!$A$2:$A$12,0)),"") -> Rodríguez Ana | H29: 10 | I29: 6 | J29: 5 | K29: =IFERROR(AVERAGE($H29:$J29),"") -> 7 | L29: =IF($K29="","",IF($K29>=6,"Aprobado","Desaprobado")) -> Aprobado | M29: Cumple con lo solicitado
A30: AL-009 | B30: =IFERROR(INDEX(Alumnos!$B$2:$B$31,MATCH($A30,Alumnos!$A$2:$A$31,0))&", "&INDEX(Alumnos!$C$2:$C$31,MATCH($A30,Alumnos!$A$2:$A$31,0)),"") -> Cabrera, Sofía | C30: 1 | D30: A | E30: Historia | F30: PR-03 | G30: =IFERROR(INDEX(Profesores!$B$2:$B$12,MATCH($F30,Profesores!$A$2:$A$12,0))&" "&INDEX(Profesores!$C$2:$C$12,MATCH($F30,Profesores!$A$2:$A$12,0)),"") -> Rodríguez Ana | H30: 8 | I30: 9 | J30: 9 | K30: =IFERROR(AVERAGE($H30:$J30),"") -> 8.6666667 | L30: =IF($K30="","",IF($K30>=6,"Aprobado","Desaprobado")) -> Aprobado
A31: AL-010 | B31: =IFERROR(INDEX(Alumnos!$B$2:$B$31,MATCH($A31,Alumnos!$A$2:$A$31,0))&", "&INDEX(Alumnos!$C$2:$C$31,MATCH($A31,Alumnos!$A$2:$A$31,0)),"") -> Núñez, Renata | C31: 1 | D31: A | E31: Historia | F31: PR-03 | G31: =IFERROR(INDEX(Profesores!$B$2:$B$12,MATCH($F31,Profesores!$A$2:$A$12,0))&" "&INDEX(Profesores!$C$2:$C$12,MATCH($F31,Profesores!$A$2:$A$12,0)),"") -> Rodríguez Ana | H31: 10 | I31: 10 | J31: 5 | K31: =IFERROR(AVERAGE($H31:$J31),"") -> 8.3333333 | L31: =IF($K31="","",IF($K31>=6,"Aprobado","Desaprobado")) -> Aprobado | M31: Necesita repasar contenidos previos
A32: AL-001 | B32: =IFERROR(INDEX(Alumnos!$B$2:$B$31,MATCH($A32,Alumnos!$A$2:$A$31,0))&", "&INDEX(Alumnos!$C$2:$C$31,MATCH($A32,Alumnos!$A$2:$A$31,0)),"") -> Ortiz, María | C32: 1 | D32: A | E32: Geografía | F32: PR-04 | G32: =IFERROR(INDEX(Profesores!$B$2:$B$12,MATCH($F32,Profesores!$A$2:$A$12,0))&" "&INDEX(Profesores!$C$2:$C$12,MATCH($F32,Profesores!$A$2:$A$12,0)),"") -> Pérez Diego | H32: 4 | I32: 8 | J32: 4 | K32: =IFERROR(AVERAGE($H32:$J32),"") -> 5.3333333 | L32: =IF($K32="","",IF($K32>=6,"Aprobado","Desaprobado")) -> Desaprobado | M32: Necesita repasar contenidos previos
A33: AL-002 | B33: =IFERROR(INDEX(Alumnos!$B$2:$B$31,MATCH($A33,Alumnos!$A$2:$A$31,0))&", "&INDEX(Alumnos!$C$2:$C$31,MATCH($A33,Alumnos!$A$2:$A$31,0)),"") -> Herrera, Delfina | C33: 1 | D33: A | E33: Geografía | F33: PR-04 | G33: =IFERROR(INDEX(Profesores!$B$2:$B$12,MATCH($F33,Profesores!$A$2:$A$12,0))&" "&INDEX(Profesores!$C$2:$C$12,MATCH($F33,Profesores!$A$2:$A$12,0)),"") -> Pérez Diego | H33: 8 | I33: 9 | J33: 7 | K33: =IFERROR(AVERAGE($H33:$J33),"") -> 8 | L33: =IF($K33="","",IF($K33>=6,"Aprobado","Desaprobado")) -> Aprobado | M33: Entrega tarde los trabajos
A34: AL-003 | B34: =IFERROR(INDEX(Alumnos!$B$2:$B$31,MATCH($A34,Alumnos!$A$2:$A$31,0))&", "&INDEX(Alumnos!$C$2:$C$31,MATCH($A34,Alumnos!$A$2:$A$31,0)),"") -> Vega, Joaquín | C34: 1 | D34: A | E34: Geografía | F34: PR-04 | G34: =IFERROR(INDEX(Profesores!$B$2:$B$12,MATCH($F34,Profesores!$A$2:$A$12,0))&" "&INDEX(Profesores!$C$2:$C$12,MATCH($F34,Profesores!$A$2:$A$12,0)),"") -> Pérez Diego | H34: 9 | I34: 5 | J34: 4 | K34: =IFERROR(AVERAGE($H34:$J34),"") -> 6 | L34: =IF($K34="","",IF($K34>=6,"Aprobado","Desaprobado")) -> Aprobado | M34: Cumple con lo solicitado
A35: AL-004 | B35: =IFERROR(INDEX(Alumnos!$B$2:$B$31,MATCH($A35,Alumnos!$A$2:$A$31,0))&", "&INDEX(Alumnos!$C$2:$C$31,MATCH($A35,Alumnos!$A$2:$A$31,0)),"") -> Silva, Tomás | C35: 1 | D35: A | E35: Geografía | F35: PR-04 | G35: =IFERROR(INDEX(Profesores!$B$2:$B$12,MATCH($F35,Profesores!$A$2:$A$12,0))&" "&INDEX(Profesores!$C$2:$C$12,MATCH($F35,Profesores!$A$2:$A$12,0)),"") -> Pérez Diego | H35: 9 | I35: 10 | J35: 9 | K35: =IFERROR(AVERAGE($H35:$J35),"") -> 9.3333333 | L35: =IF($K35="","",IF($K35>=6,"Aprobado","Desaprobado")) -> Aprobado | M35: Muy buen desempeño
A36: AL-005 | B36: =IFERROR(INDEX(Alumnos!$B$2:$B$31,MATCH($A36,Alumnos!$A$2:$A$31,0))&", "&INDEX(Alumnos!$C$2:$C$31,MATCH($A36,Alumnos!$A$2:$A$31,0)),"") -> Sánchez, Franco | C36: 1 | D36: A | E36: Geografía | F36: PR-04 | G36: =IFERROR(INDEX(Profesores!$B$2:$B$12,MATCH($F36,Profesores!$A$2:$A$12,0))&" "&INDEX(Profesores!$C$2:$C$12,MATCH($F36,Profesores!$A$2:$A$12,0)),"") -> Pérez Diego | H36: 4 | I36: 9 | J36: 10 | K36: =IFERROR(AVERAGE($H36:$J36),"") -> 7.6666667 | L36: =IF($K36="","",IF($K36>=6,"Aprobado","Desaprobado")) -> Aprobado | M36: Necesita repasar contenidos previos
A37: AL-006 | B37: =IFERROR(INDEX(Alumnos!$B$2:$B$31,MATCH($A37,Alumnos!$A$2:$A$31,0))&", "&INDEX(Alumnos!$C$2:$C$31,MATCH($A37,Alumnos!$A$2:$A$31,0)),"") -> Luna, Iván | C37: 1 | D37: A | E37: Geografía | F37: PR-04 | G37: =IFERROR(INDEX(Profesores!$B$2:$B$12,MATCH($F37,Profesores!$A$2:$A$12,0))&" "&INDEX(Profesores!$C$2:$C$12,MATCH($F37,Profesores!$A$2:$A$12,0)),"") -> Pérez Diego | H37: 10 | I37: 9 | J37: 8 | K37: =IFERROR(AVERAGE($H37:$J37),"") -> 9 | L37: =IF($K37="","",IF($K37>=6,"Aprobado","Desaprobado")) -> Aprobado
A38: AL-007 | B38: =IFERROR(INDEX(Alumnos!$B$2:$B$31,MATCH($A38,Alumnos!$A$2:$A$31,0))&", "&INDEX(Alumnos!$C$2:$C$31,MATCH($A38,Alumnos!$A$2:$A$31,0)),"") -> Medina, Valentina | C38: 1 | D38: A | E38: Geografía | F38: PR-04 | G38: =IFERROR(INDEX(Profesores!$B$2:$B$12,MATCH($F38,Profesores!$A$2:$A$12,0))&" "&INDEX(Profesores!$C$2:$C$12,MATCH($F38,Profesores!$A$2:$A$12,0)),"") -> Pérez Diego | H38: 10 | I38: 8 | J38: 10 | K38: =IFERROR(AVERAGE($H38:$J38),"") -> 9.3333333 | L38: =IF($K38="","",IF($K38>=6,"Aprobado","Desaprobado")) -> Aprobado
A39: AL-008 | B39: =IFERROR(INDEX(Alumnos!$B$2:$B$31,MATCH($A39,Alumnos!$A$2:$A$31,0))&", "&INDEX(Alumnos!$C$2:$C$31,MATCH($A39,Alumnos!$A$2:$A$31,0)),"") -> Rojas, María | C39: 1 | D39: A | E39: Geografía | F39: PR-04 | G39: =IFERROR(INDEX(Profesores!$B$2:$B$12,MATCH($F39,Profesores!$A$2:$A$12,0))&" "&INDEX(Profesores!$C$2:$C$12,MATCH($F39,Profesores!$A$2:$A$12,0)),"") -> Pérez Diego | H39: 6 | I39: 8 | J39: 7 | K39: =IFERROR(AVERAGE($H39:$J39),"") -> 7 | L39: =IF($K39="","",IF($K39>=6,"Aprobado","Desaprobado")) -> Aprobado | M39: Buena participación en clase
A40: AL-009 | B40: =IFERROR(INDEX(Alumnos!$B$2:$B$31,MATCH($A40,Alumnos!$A$2:$A$31,0))&", "&INDEX(Alumnos!$C$2:$C$31,MATCH($A40,Alumnos!$A$2:$A$31,0)),"") -> Cabrera, Sofía | C40: 1 | D40: A | E40: Geografía | F40: PR-04 | G40: =IFERROR(INDEX(Profesores!$B$2:$B$12,MATCH($F40,Profesores!$A$2:$A$12,0))&" "&INDEX(Profesores!$C$2:$C$12,MATCH($F40,Profesores!$A$2:$A$12,0)),"") -> Pérez Diego | H40: 4 | I40: 8 | J40: 9 | K40: =IFERROR(AVERAGE($H40:$J40),"") -> 7 | L40: =IF($K40="","",IF($K40>=6,"Aprobado","Desaprobado")) -> Aprobado | M40: Buena participación en clase
...

Sheet Asistencia
A1: Fecha | B1: Año | C1: División | D1: Turno | E1: ID_Alumno | F1: Alumno | G1: Estado | H1: Observación_Preceptor
A2: 02/09/2026 | B2: 1 | C2: A | D2: Mañana | E2: AL-001 | F2: =IFERROR(INDEX(Alumnos!$B$2:$B$31,MATCH($E2,Alumnos!$A$2:$A$31,0))&", "&INDEX(Alumnos!$C$2:$C$31,MATCH($E2,Alumnos!$A$2:$A$31,0)),"") -> Ortiz, María | G2: Ausente
A3: 02/09/2026 | B3: 1 | C3: A | D3: Mañana | E3: AL-002 | F3: =IFERROR(INDEX(Alumnos!$B$2:$B$31,MATCH($E3,Alumnos!$A$2:$A$31,0))&", "&INDEX(Alumnos!$C$2:$C$31,MATCH($E3,Alumnos!$A$2:$A$31,0)),"") -> Herrera, Delfina | G3: Tarde | H3: Llegó 15 min tarde
A4: 02/09/2026 | B4: 1 | C4: A | D4: Mañana | E4: AL-003 | F4: =IFERROR(INDEX(Alumnos!$B$2:$B$31,MATCH($E4,Alumnos!$A$2:$A$31,0))&", "&INDEX(Alumnos!$C$2:$C$31,MATCH($E4,Alumnos!$A$2:$A$31,0)),"") -> Vega, Joaquín | G4: Presente
A5: 02/09/2026 | B5: 1 | C5: A | D5: Mañana | E5: AL-004 | F5: =IFERROR(INDEX(Alumnos!$B$2:$B$31,MATCH($E5,Alumnos!$A$2:$A$31,0))&", "&INDEX(Alumnos!$C$2:$C$31,MATCH($E5,Alumnos!$A$2:$A$31,0)),"") -> Silva, Tomás | G5: Justificada | H5: Certificado médico presentado
A6: 02/09/2026 | B6: 1 | C6: A | D6: Mañana | E6: AL-005 | F6: =IFERROR(INDEX(Alumnos!$B$2:$B$31,MATCH($E6,Alumnos!$A$2:$A$31,0))&", "&INDEX(Alumnos!$C$2:$C$31,MATCH($E6,Alumnos!$A$2:$A$31,0)),"") -> Sánchez, Franco | G6: Tarde | H6: Llegó 15 min tarde
A7: 02/09/2026 | B7: 1 | C7: A | D7: Mañana | E7: AL-006 | F7: =IFERROR(INDEX(Alumnos!$B$2:$B$31,MATCH($E7,Alumnos!$A$2:$A$31,0))&", "&INDEX(Alumnos!$C$2:$C$31,MATCH($E7,Alumnos!$A$2:$A$31,0)),"") -> Luna, Iván | G7: Presente
A8: 02/09/2026 | B8: 1 | C8: A | D8: Mañana | E8: AL-007 | F8: =IFERROR(INDEX(Alumnos!$B$2:$B$31,MATCH($E8,Alumnos!$A$2:$A$31,0))&", "&INDEX(Alumnos!$C$2:$C$31,MATCH($E8,Alumnos!$A$2:$A$31,0)),"") -> Medina, Valentina | G8: Presente
A9: 02/09/2026 | B9: 1 | C9: A | D9: Mañana | E9: AL-008 | F9: =IFERROR(INDEX(Alumnos!$B$2:$B$31,MATCH($E9,Alumnos!$A$2:$A$31,0))&", "&INDEX(Alumnos!$C$2:$C$31,MATCH($E9,Alumnos!$A$2:$A$31,0)),"") -> Rojas, María | G9: Presente
A10: 02/09/2026 | B10: 1 | C10: A | D10: Mañana | E10: AL-009 | F10: =IFERROR(INDEX(Alumnos!$B$2:$B$31,MATCH($E10,Alumnos!$A$2:$A$31,0))&", "&INDEX(Alumnos!$C$2:$C$31,MATCH($E10,Alumnos!$A$2:$A$31,0)),"") -> Cabrera, Sofía | G10: Tarde | H10: Llegó 15 min tarde
A11: 02/09/2026 | B11: 1 | C11: A | D11: Mañana | E11: AL-010 | F11: =IFERROR(INDEX(Alumnos!$B$2:$B$31,MATCH($E11,Alumnos!$A$2:$A$31,0))&", "&INDEX(Alumnos!$C$2:$C$31,MATCH($E11,Alumnos!$A$2:$A$31,0)),"") -> Núñez, Renata | G11: Justificada | H11: Certificado médico presentado
A12: 02/09/2026 | B12: 2 | C12: A | D12: Mañana | E12: AL-011 | F12: =IFERROR(INDEX(Alumnos!$B$2:$B$31,MATCH($E12,Alumnos!$A$2:$A$31,0))&", "&INDEX(Alumnos!$C$2:$C$31,MATCH($E12,Alumnos!$A$2:$A$31,0)),"") -> Pérez, Emilia | G12: Presente
A13: 02/09/2026 | B13: 2 | C13: A | D13: Mañana | E13: AL-012 | F13: =IFERROR(INDEX(Alumnos!$B$2:$B$31,MATCH($E13,Alumnos!$A$2:$A$31,0))&", "&INDEX(Alumnos!$C$2:$C$31,MATCH($E13,Alumnos!$A$2:$A$31,0)),"") -> Aguirre, Camila | G13: Tarde | H13: Llegó 15 min tarde
A14: 02/09/2026 | B14: 2 | C14: A | D14: Mañana | E14: AL-013 | F14: =IFERROR(INDEX(Alumnos!$B$2:$B$31,MATCH($E14,Alumnos!$A$2:$A$31,0))&", "&INDEX(Alumnos!$C$2:$C$31,MATCH($E14,Alumnos!$A$2:$A$31,0)),"") -> Aguirre, Guadalupe | G14: Ausente
A15: 02/09/2026 | B15: 2 | C15: A | D15: Mañana | E15: AL-014 | F15: =IFERROR(INDEX(Alumnos!$B$2:$B$31,MATCH($E15,Alumnos!$A$2:$A$31,0))&", "&INDEX(Alumnos!$C$2:$C$31,MATCH($E15,Alumnos!$A$2:$A$31,0)),"") -> Acosta, Bruno | G15: Justificada | H15: Certificado médico presentado
A16: 02/09/2026 | B16: 2 | C16: A | D16: Mañana | E16: AL-015 | F16: =IFERROR(INDEX(Alumnos!$B$2:$B$31,MATCH($E16,Alumnos!$A$2:$A$31,0))&", "&INDEX(Alumnos!$C$2:$C$31,MATCH($E16,Alumnos!$A$2:$A$31,0)),"") -> Flores, Valentina | G16: Tarde | H16: Llegó 15 min tarde
A17: 02/09/2026 | B17: 2 | C17: A | D17: Mañana | E17: AL-016 | F17: =IFERROR(INDEX(Alumnos!$B$2:$B$31,MATCH($E17,Alumnos!$A$2:$A$31,0))&", "&INDEX(Alumnos!$C$2:$C$31,MATCH($E17,Alumnos!$A$2:$A$31,0)),"") -> Aguirre, Juan | G17: Tarde | H17: Llegó 15 min tarde
A18: 02/09/2026 | B18: 2 | C18: A | D18: Mañana | E18: AL-017 | F18: =IFERROR(INDEX(Alumnos!$B$2:$B$31,MATCH($E18,Alumnos!$A$2:$A$31,0))&", "&INDEX(Alumnos!$C$2:$C$31,MATCH($E18,Alumnos!$A$2:$A$31,0)),"") -> Ruiz, Camila | G18: Presente
A19: 02/09/2026 | B19: 2 | C19: A | D19: Mañana | E19: AL-018 | F19: =IFERROR(INDEX(Alumnos!$B$2:$B$31,MATCH($E19,Alumnos!$A$2:$A$31,0))&", "&INDEX(Alumnos!$C$2:$C$31,MATCH($E19,Alumnos!$A$2:$A$31,0)),"") -> Castro, Nicolás | G19: Ausente
A20: 02/09/2026 | B20: 2 | C20: A | D20: Mañana | E20: AL-019 | F20: =IFERROR(INDEX(Alumnos!$B$2:$B$31,MATCH($E20,Alumnos!$A$2:$A$31,0))&", "&INDEX(Alumnos!$C$2:$C$31,MATCH($E20,Alumnos!$A$2:$A$31,0)),"") -> Suárez, Julieta | G20: Tarde | H20: Llegó 15 min tarde
A21: 02/09/2026 | B21: 2 | C21: A | D21: Mañana | E21: AL-020 | F21: =IFERROR(INDEX(Alumnos!$B$2:$B$31,MATCH($E21,Alumnos!$A$2:$A$31,0))&", "&INDEX(Alumnos!$C$2:$C$31,MATCH($E21,Alumnos!$A$2:$A$31,0)),"") -> Vega, Benjamín | G21: Ausente
A22: 02/09/2026 | B22: 3 | C22: A | D22: Tarde | E22: AL-021 | F22: =IFERROR(INDEX(Alumnos!$B$2:$B$31,MATCH($E22,Alumnos!$A$2:$A$31,0))&", "&INDEX(Alumnos!$C$2:$C$31,MATCH($E22,Alumnos!$A$2:$A$31,0)),"") -> Molina, Milagros | G22: Presente
A23: 02/09/2026 | B23: 3 | C23: A | D23: Tarde | E23: AL-022 | F23: =IFERROR(INDEX(Alumnos!$B$2:$B$31,MATCH($E23,Alumnos!$A$2:$A$31,0))&", "&INDEX(Alumnos!$C$2:$C$31,MATCH($E23,Alumnos!$A$2:$A$31,0)),"") -> Rodríguez, Renata | G23: Ausente
A24: 02/09/2026 | B24: 3 | C24: A | D24: Tarde | E24: AL-023 | F24: =IFERROR(INDEX(Alumnos!$B$2:$B$31,MATCH($E24,Alumnos!$A$2:$A$31,0))&", "&INDEX(Alumnos!$C$2:$C$31,MATCH($E24,Alumnos!$A$2:$A$31,0)),"") -> Peralta, Franco | G24: Presente
A25: 02/09/2026 | B25: 3 | C25: A | D25: Tarde | E25: AL-024 | F25: =IFERROR(INDEX(Alumnos!$B$2:$B$31,MATCH($E25,Alumnos!$A$2:$A$31,0))&", "&INDEX(Alumnos!$C$2:$C$31,MATCH($E25,Alumnos!$A$2:$A$31,0)),"") -> Sánchez, Renata | G25: Justificada | H25: Certificado médico presentado
A26: 02/09/2026 | B26: 3 | C26: A | D26: Tarde | E26: AL-025 | F26: =IFERROR(INDEX(Alumnos!$B$2:$B$31,MATCH($E26,Alumnos!$A$2:$A$31,0))&", "&INDEX(Alumnos!$C$2:$C$31,MATCH($E26,Alumnos!$A$2:$A$31,0)),"") -> Martínez, Benjamín | G26: Presente
A27: 02/09/2026 | B27: 3 | C27: A | D27: Tarde | E27: AL-026 | F27: =IFERROR(INDEX(Alumnos!$B$2:$B$31,MATCH($E27,Alumnos!$A$2:$A$31,0))&", "&INDEX(Alumnos!$C$2:$C$31,MATCH($E27,Alumnos!$A$2:$A$31,0)),"") -> Medina, María | G27: Presente
A28: 02/09/2026 | B28: 3 | C28: A | D28: Tarde | E28: AL-027 | F28: =IFERROR(INDEX(Alumnos!$B$2:$B$31,MATCH($E28,Alumnos!$A$2:$A$31,0))&", "&INDEX(Alumnos!$C$2:$C$31,MATCH($E28,Alumnos!$A$2:$A$31,0)),"") -> Molina, Facundo | G28: Presente
A29: 02/09/2026 | B29: 3 | C29: A | D29: Tarde | E29: AL-028 | F29: =IFERROR(INDEX(Alumnos!$B$2:$B$31,MATCH($E29,Alumnos!$A$2:$A$31,0))&", "&INDEX(Alumnos!$C$2:$C$31,MATCH($E29,Alumnos!$A$2:$A$31,0)),"") -> Álvarez, Pilar | G29: Presente
A30: 02/09/2026 | B30: 3 | C30: A | D30: Tarde | E30: AL-029 | F30: =IFERROR(INDEX(Alumnos!$B$2:$B$31,MATCH($E30,Alumnos!$A$2:$A$31,0))&", "&INDEX(Alumnos!$C$2:$C$31,MATCH($E30,Alumnos!$A$2:$A$31,0)),"") -> Suárez, Pilar | G30: Tarde | H30: Llegó 15 min tarde
A31: 02/09/2026 | B31: 3 | C31: A | D31: Tarde | E31: AL-030 | F31: =IFERROR(INDEX(Alumnos!$B$2:$B$31,MATCH($E31,Alumnos!$A$2:$A$31,0))&", "&INDEX(Alumnos!$C$2:$C$31,MATCH($E31,Alumnos!$A$2:$A$31,0)),"") -> Sánchez, Facundo | G31: Presente
A32: 03/09/2026 | B32: 1 | C32: A | D32: Mañana | E32: AL-001 | F32: =IFERROR(INDEX(Alumnos!$B$2:$B$31,MATCH($E32,Alumnos!$A$2:$A$31,0))&", "&INDEX(Alumnos!$C$2:$C$31,MATCH($E32,Alumnos!$A$2:$A$31,0)),"") -> Ortiz, María | G32: Ausente
A33: 03/09/2026 | B33: 1 | C33: A | D33: Mañana | E33: AL-002 | F33: =IFERROR(INDEX(Alumnos!$B$2:$B$31,MATCH($E33,Alumnos!$A$2:$A$31,0))&", "&INDEX(Alumnos!$C$2:$C$31,MATCH($E33,Alumnos!$A$2:$A$31,0)),"") -> Herrera, Delfina | G33: Presente
A34: 03/09/2026 | B34: 1 | C34: A | D34: Mañana | E34: AL-003 | F34: =IFERROR(INDEX(Alumnos!$B$2:$B$31,MATCH($E34,Alumnos!$A$2:$A$31,0))&", "&INDEX(Alumnos!$C$2:$C$31,MATCH($E34,Alumnos!$A$2:$A$31,0)),"") -> Vega, Joaquín | G34: Presente
A35: 03/09/2026 | B35: 1 | C35: A | D35: Mañana | E35: AL-004 | F35: =IFERROR(INDEX(Alumnos!$B$2:$B$31,MATCH($E35,Alumnos!$A$2:$A$31,0))&", "&INDEX(Alumnos!$C$2:$C$31,MATCH($E35,Alumnos!$A$2:$A$31,0)),"") -> Silva, Tomás | G35: Ausente
A36: 03/09/2026 | B36: 1 | C36: A | D36: Mañana | E36: AL-005 | F36: =IFERROR(INDEX(Alumnos!$B$2:$B$31,MATCH($E36,Alumnos!$A$2:$A$31,0))&", "&INDEX(Alumnos!$C$2:$C$31,MATCH($E36,Alumnos!$A$2:$A$31,0)),"") -> Sánchez, Franco | G36: Presente
A37: 03/09/2026 | B37: 1 | C37: A | D37: Mañana | E37: AL-006 | F37: =IFERROR(INDEX(Alumnos!$B$2:$B$31,MATCH($E37,Alumnos!$A$2:$A$31,0))&", "&INDEX(Alumnos!$C$2:$C$31,MATCH($E37,Alumnos!$A$2:$A$31,0)),"") -> Luna, Iván | G37: Tarde | H37: Llegó 15 min tarde
A38: 03/09/2026 | B38: 1 | C38: A | D38: Mañana | E38: AL-007 | F38: =IFERROR(INDEX(Alumnos!$B$2:$B$31,MATCH($E38,Alumnos!$A$2:$A$31,0))&", "&INDEX(Alumnos!$C$2:$C$31,MATCH($E38,Alumnos!$A$2:$A$31,0)),"") -> Medina, Valentina | G38: Ausente
A39: 03/09/2026 | B39: 1 | C39: A | D39: Mañana | E39: AL-008 | F39: =IFERROR(INDEX(Alumnos!$B$2:$B$31,MATCH($E39,Alumnos!$A$2:$A$31,0))&", "&INDEX(Alumnos!$C$2:$C$31,MATCH($E39,Alumnos!$A$2:$A$31,0)),"") -> Rojas, María | G39: Tarde | H39: Llegó 15 min tarde
A40: 03/09/2026 | B40: 1 | C40: A | D40: Mañana | E40: AL-009 | F40: =IFERROR(INDEX(Alumnos!$B$2:$B$31,MATCH($E40,Alumnos!$A$2:$A$31,0))&", "&INDEX(Alumnos!$C$2:$C$31,MATCH($E40,Alumnos!$A$2:$A$31,0)),"") -> Cabrera, Sofía | G40: Presente
...
